Workbook

Sheet My trades
A1: Trade | B1: Stock exchange | C1: Region | D1: Date added | E1: Quantity | F1: Buy Price | G1: Date sold | H1: Sell Price
A2: agfgcfxt | B2: Bombay Stock Exchange | C2: India | D2: 44841 | E2: 7 | F2: 0.28318547 | G2: 45092 | H2: 0.55712981
A3: aieoltom | B3: Tehran Stock Exchange | C3: Iran | D3: 44200 | E3: 2 | F3: 0.64142747 | G3: 45039 | H3: 0.88983598
A4: almuieaq | B4: National Stock Exchange | C4: India | D4: 44519 | E4: 6 | F4: 0.98092818 | G4: 44968 | H4: 0.72256313
A5: apxkynfx | B5: SIX Swiss Exchange | C5: Switzerland | D5: 44664 | E5: 1 | F5: 0.4602753 | G5: 44971 | H5: 0.8279317
A6: bbjeprsq | B6: Bombay Stock Exchange | C6: India | D6: 44351 | E6: 9 | F6: 0.55179845 | G6: 44977 | H6: 0.19789786
A7: bcizkhng | B7: Euronext | C7: Europe | D7: 44529 | E7: 1 | F7: 0.30386849 | G7: 44969 | H7: 0.97814413
A8: bdkloegq | B8: Korea Exchange | C8: South Korea | D8: 44500 | E8: 3 | F8: 0.10094556 | G8: 44930 | H8: 0.40740538
A9: beszhcyh | B9: Johannesburg Stock Exchange | C9: South Africa | D9: 44584 | E9: 4 | F9: 0.1365207 | G9: 44991 | H9: 0.38969057
A10: bjfxoyxb | B10: Toronto Stock Exchange | C10: Canada | D10: 44472 | E10: 10 | F10: 0.41670439 | G10: 45045 | H10: 0.54934508
A11: bpjmrhjo | B11: Euronext | C11: Europe | D11: 44587 | E11: 6 | F11: 0.24316987 | G11: 44987 | H11: 0.42023282
A12: brxwzrct | B12: Deutsche Börse AG | C12: Germany | D12: 44407 | E12: 5 | F12: 0.80079383 | G12: 44996 | H12: 0.8966623
A13: bumcnvke | B13: Bombay Stock Exchange | C13: India | D13: 44543 | E13: 10 | F13: 0.63898127 | G13: 45031 | H13: 0.77496722
... A201: zvxjotpr | B201: B3 Brasil Bolsa Balcão | C201: Brazil | D201: 44502 | E201: 8 | F201: 0.91352809 | G201: 44978 | H201: 0.13798579
D203: ​

Sheet Stock exchanges
A1: Region | B1: Stock exchange | C1: Num of Trades | D1: Mandatory to pay taxes
A2: Australia | C2: 80 | D2: =IF(B2<> "","", IF(C2>=67,"yes","no")) -> yes
B3: Australian Securities Exchange | C3: 80 | D3: =IF(B3<> "","", IF(C3>=67,"yes","no"))
A4: Brazil | C4: 83 | D4: =IF(B4<> "","", IF(C4>=67,"yes","no")) -> yes
B5: B3 Brasil Bolsa Balcão | C5: 83 | D5: =IF(B5<> "","", IF(C5>=67,"yes","no"))
A6: Canada | C6: 46 | D6: =IF(B6<> "","", IF(C6>=67,"yes","no")) -> no
B7: Toronto Stock Exchange | C7: 46 | D7: =IF(B7<> "","", IF(C7>=67,"yes","no"))
A8: China | C8: 74 | D8: =IF(B8<> "","", IF(C8>=67,"yes","no")) -> yes
B9: Shanghai Stock Exchange | C9: 39 | D9: =IF(B9<> "","", IF(C9>=67,"yes","no"))
B10: Shenzhen Stock Exchange | C10: 35 | D10: =IF(B10<> "","", IF(C10>=67,"yes","no"))
A11: Europe | C11: 70 | D11: =IF(B11<> "","", IF(C11>=67,"yes","no")) -> yes
B12: Euronext | C12: 30 | D12: =IF(B12<> "","", IF(C12>=67,"yes","no"))
B13: Nasdaq Nordic and Baltic Exchanges | C13: 40 | D13: =IF(B13<> "","", IF(C13>=67,"yes","no"))
A14: Germany | C14: 81 | D14: =IF(B14<> "","", IF(C14>=67,"yes","no")) -> yes
B15: Deutsche Börse AG | C15: 81 | D15: =IF(B15<> "","", IF(C15>=67,"yes","no"))
A16: Hong Kong | C16: 54 | D16: =IF(B16<> "","", IF(C16>=67,"yes","no")) -> no
B17: Hong Kong Stock Exchange | C17: 54 | D17: =IF(B17<> "","", IF(C17>=67,"yes","no"))
A18: India | C18: 111 | D18: =IF(B18<> "","", IF(C18>=67,"yes","no")) -> yes
B19: Bombay Stock Exchange | C19: 75 | D19: =IF(B19<> "","", IF(C19>=67,"yes","no"))
B20: National Stock Exchange | C20: 36 | D20: =IF(B20<> "","", IF(C20>=67,"yes","no"))
A21: Iran | C21: 40 | D21: =IF(B21<> "","", IF(C21>=67,"yes","no")) -> no
B22: Tehran Stock Exchange | C22: 40 | D22: =IF(B22<> "","", IF(C22>=67,"yes","no"))
A23: Japan | C23: 43 | D23: =IF(B23<> "","", IF(C23>=67,"yes","no")) -> no
B24: Japan Exchange Group | C24: 43 | D24: =IF(B24<> "","", IF(C24>=67,"yes","no"))
A25: Saudi Arabia | C25: 35 | D25: =IF(B25<> "","", IF(C25>=67,"yes","no")) -> no
B26: Saudi Stock Exchange (Tadawul) | C26: 35 | D26: =IF(B26<> "","", IF(C26>=67,"yes","no"))
A27: South Africa | C27: 34 | D27: =IF(B27<> "","", IF(C27>=67,"yes","no")) -> no
B28: Johannesburg Stock Exchange | C28: 34 | D28: =IF(B28<> "","", IF(C28>=67,"yes","no"))
A29: South Korea | C29: 36 | D29: =IF(B29<> "","", IF(C29>=67,"yes","no")) -> no
B30: Korea Exchange | C30: 36 | D30: =IF(B30<> "","", IF(C30>=67,"yes","no"))
A31: Switzerland | C31: 49 | D31: =IF(B31<> "","", IF(C31>=67,"yes","no")) -> no
B32: SIX Swiss Exchange | C32: 49 | D32: =IF(B32<> "","", IF(C32>=67,"yes","no"))
A33: Taiwan | C33: 57 | D33: =IF(B33<> "","", IF(C33>=67,"yes","no")) -> no
B34: Taiwan Stock Exchange | C34: 57 | D34: =IF(B34<> "","", IF(C34>=67,"yes","no"))
A35: United Kingdom | C35: 38 | D35: =IF(B35<> "","", IF(C35>=67,"yes","no")) -> no
B36: London Stock Exchange | C36: 38 | D36: =IF(B36<> "","", IF(C36>=67,"yes","no"))
A37: United States | C37: 88 | D37: =IF(B37<> "","", IF(C37>=67,"yes","no")) -> yes
B38: Nasdaq | C38: 42 | D38: =IF(B38<> "","", IF(C38>=67,"yes","no"))
B39: New York Stock Exchange | C39: 46 | D39: =IF(B39<> "","", IF(C39>=67,"yes","no"))
A40: Totale complessivo | C40: 1019

Sheet Profit insights
A1: Trade ID | B1: Duration | C1: Profit
A2: ='My trades'!A60 -> hpvfzslv | B2: =_xlfn.DAYS('My trades'!G60,'My trades'!D60) -> 30 | C2: =('My trades'!H60-'My trades'!F60)*'My trades'!E60 -> 1.1391515
A3: ='My trades'!A113 -> oplgqwal | B3: =_xlfn.DAYS('My trades'!G113,'My trades'!D113) -> 42 | C3: =('My trades'!H113-'My trades'!F113)*'My trades'!E113 -> -6.419612
A4: ='My trades'!A26 -> dpaxyvrx | B4: =_xlfn.DAYS('My trades'!G26,'My trades'!D26) -> 51 | C4: =('My trades'!H26-'My trades'!F26)*'My trades'!E26 -> -0.32528107
A5: ='My trades'!A101 -> mxmztjnk | B5: =_xlfn.DAYS('My trades'!G101,'My trades'!D101) -> 57 | C5: =('My trades'!H101-'My trades'!F101)*'My trades'!E101 -> 1.1022958
A6: ='My trades'!A123 -> pyljmfku | B6: =_xlfn.DAYS('My trades'!G123,'My trades'!D123) -> 58 | C6: =('My trades'!H123-'My trades'!F123)*'My trades'!E123 -> -3.7137818
A7: ='My trades'!A103 -> nheepbxg | B7: =_xlfn.DAYS('My trades'!G103,'My trades'!D103) -> 69 | C7: =('My trades'!H103-'My trades'!F103)*'My trades'!E103 -> -2.6947242
A8: ='My trades'!A41 -> fucpzbpk | B8: =_xlfn.DAYS('My trades'!G41,'My trades'!D41) -> 71 | C8: =('My trades'!H41-'My trades'!F41)*'My trades'!E41 -> -1.6706743
A9: ='My trades'!A17 -> ciykrilb | B9: =_xlfn.DAYS('My trades'!G17,'My trades'!D17) -> 78 | C9: =('My trades'!H17-'My trades'!F17)*'My trades'!E17 -> -4.0381768
A10: ='My trades'!A187 -> yjrqvwdc | B10: =_xlfn.DAYS('My trades'!G187,'My trades'!D187) -> 80 | C10: =('My trades'!H187-'My trades'!F187)*'My trades'!E187 -> -0.13532525
A11: ='My trades'!A152 -> twxakkhn | B11: =_xlfn.DAYS('My trades'!G152,'My trades'!D152) -> 87 | C11: =('My trades'!H152-'My trades'!F152)*'My trades'!E152 -> 2.332716
A12: ='My trades'!A70 -> jarhgmub | B12: =_xlfn.DAYS('My trades'!G70,'My trades'!D70) -> 88 | C12: =('My trades'!H70-'My trades'!F70)*'My trades'!E70 -> 0.43584937
A13: ='My trades'!A43 -> gcndrwci | B13: =_xlfn.DAYS('My trades'!G43,'My trades'!D43) -> 106 | C13: =('My trades'!H43-'My trades'!F43)*'My trades'!E43 -> 1.7198007
A14: ='My trades'!A14 -> cesjzpbs | B14: =_xlfn.DAYS('My trades'!G14,'My trades'!D14) -> 109 | C14: =('My trades'!H14-'My trades'!F14)*'My trades'!E14 -> 2.9151707
A15: ='My trades'!A145 -> tgayvhvz | B15: =_xlfn.DAYS('My trades'!G145,'My trades'!D145) -> 123 | C15: =('My trades'!H145-'My trades'!F145)*'My trades'!E145 -> 0.63398607
A16: ='My trades'!A108 -> nuleyiit | B16: =_xlfn.DAYS('My trades'!G108,'My trades'!D108) -> 126 | C16: =('My trades'!H108-'My trades'!F108)*'My trades'!E108 -> 2.0673886
A17: ='My trades'!A38 -> fjhbimle | B17: =_xlfn.DAYS('My trades'!G38,'My trades'!D38) -> 130 | C17: =('My trades'!H38-'My trades'!F38)*'My trades'!E38 -> -0.41919268
A18: ='My trades'!A158 -> uijhzhtp | B18: =_xlfn.DAYS('My trades'!G158,'My trades'!D158) -> 141 | C18: =('My trades'!H158-'My trades'!F158)*'My trades'!E158 -> -0.33733947
A19: ='My trades'!A169 -> waxzujox | B19: =_xlfn.DAYS('My trades'!G169,'My trades'!D169) -> 143 | C19: =('My trades'!H169-'My trades'!F169)*'My trades'!E169 -> 0.03317406
A20: ='My trades'!A170 -> wfglkcmq | B20: =_xlfn.DAYS('My trades'!G170,'My trades'!D170) -> 143 | C20: =('My trades'!H170-'My trades'!F170)*'My trades'!E170 -> 0.44657129
A21: ='My trades'!A140 -> seszlhqz | B21: =_xlfn.DAYS('My trades'!G140,'My trades'!D140) -> 146 | C21: =('My trades'!H140-'My trades'!F140)*'My trades'!E140 -> 0.821921
A22: ='My trades'!A164 -> vajwbmmv | B22: =_xlfn.DAYS('My trades'!G164,'My trades'!D164) -> 148 | C22: =('My trades'!H164-'My trades'!F164)*'My trades'!E164 -> -0.28002139
A23: ='My trades'!A127 -> qexyofhb | B23: =_xlfn.DAYS('My trades'!G127,'My trades'!D127) -> 152 | C23: =('My trades'!H127-'My trades'!F127)*'My trades'!E127 -> -0.54187349
A24: ='My trades'!A199 -> zsbkamjf | B24: =_xlfn.DAYS('My trades'!G199,'My trades'!D199) -> 159 | C24: =('My trades'!H199-'My trades'!F199)*'My trades'!E199 -> 1.4526226
A25: ='My trades'!A56 -> hfwtmipz | B25: =_xlfn.DAYS('My trades'!G56,'My trades'!D56) -> 162 | C25: =('My trades'!H56-'My trades'!F56)*'My trades'!E56 -> 2.8245213
A26: ='My trades'!A109 -> nzyednpn | B26: =_xlfn.DAYS('My trades'!G109,'My trades'!D109) -> 163 | C26: =('My trades'!H109-'My trades'!F109)*'My trades'!E109 -> 4.3623327
A27: ='My trades'!A138 -> seaeoiib | B27: =_xlfn.DAYS('My trades'!G138,'My trades'!D138) -> 169 | C27: =('My trades'!H138-'My trades'!F138)*'My trades'!E138 -> -1.352458
A28: ='My trades'!A177 -> xgimgqvp | B28: =_xlfn.DAYS('My trades'!G177,'My trades'!D177) -> 172 | C28: =('My trades'!H177-'My trades'!F177)*'My trades'!E177 -> -1.5256033
A29: ='My trades'!A125 -> pywztrno | B29: =_xlfn.DAYS('My trades'!G125,'My trades'!D125) -> 175 | C29: =('My trades'!H125-'My trades'!F125)*'My trades'!E125 -> -0.51703472
A30: ='My trades'!A63 -> iagrfath | B30: =_xlfn.DAYS('My trades'!G63,'My trades'!D63) -> 181 | C30: =('My trades'!H63-'My trades'!F63)*'My trades'!E63 -> 0.40069794
A31: ='My trades'!A193 -> ywfotaaf | B31: =_xlfn.DAYS('My trades'!G193,'My trades'!D193) -> 181 | C31: =('My trades'!H193-'My trades'!F193)*'My trades'!E193 -> -0.66490583
A32: ='My trades'!A120 -> pswtoazn | B32: =_xlfn.DAYS('My trades'!G120,'My trades'!D120) -> 184 | C32: =('My trades'!H120-'My trades'!F120)*'My trades'!E120 -> -0.62322749
A33: ='My trades'!A80 -> kmlcsefq | B33: =_xlfn.DAYS('My trades'!G80,'My trades'!D80) -> 199 | C33: =('My trades'!H80-'My trades'!F80)*'My trades'!E80 -> -0.20085806
A34: ='My trades'!A69 -> iztdnkqz | B34: =_xlfn.DAYS('My trades'!G69,'My trades'!D69) -> 204 | C34: =('My trades'!H69-'My trades'!F69)*'My trades'!E69 -> -2.5716033
A35: ='My trades'!A27 -> dspetbsq | B35: =_xlfn.DAYS('My trades'!G27,'My trades'!D27) -> 207 | C35: =('My trades'!H27-'My trades'!F27)*'My trades'!E27 -> -5.4295327
A36: ='My trades'!A87 -> kwbxqlin | B36: =_xlfn.DAYS('My trades'!G87,'My trades'!D87) -> 207 | C36: =('My trades'!H87-'My trades'!F87)*'My trades'!E87 -> 5.5166452
A37: ='My trades'!A85 -> kqbdcljv | B37: =_xlfn.DAYS('My trades'!G85,'My trades'!D85) -> 212 | C37: =('My trades'!H85-'My trades'!F85)*'My trades'!E85 -> 1.3297795
A38: ='My trades'!A167 -> vnkvbrpg | B38: =_xlfn.DAYS('My trades'!G167,'My trades'!D167) -> 213 | C38: =('My trades'!H167-'My trades'!F167)*'My trades'!E167 -> 3.0343474
A39: ='My trades'!A72 -> jhrvrggo | B39: =_xlfn.DAYS('My trades'!G72,'My trades'!D72) -> 222 | C39: =('My trades'!H72-'My trades'!F72)*'My trades'!E72 -> 0.078785101
A40: ='My trades'!A45 -> giuqiukz | B40: =_xlfn.DAYS('My trades'!G45,'My trades'!D45) -> 227 | C40: =('My trades'!H45-'My trades'!F45)*'My trades'!E45 -> -0.55470984
...

Sheet Number of trades exchanged
C1: Number of trades
C2: 1 | D2: 2 | E2: 3 | F2: 4 | G2: 5 | H2: 6 | I2: 7 | J2: 8 | K2: 9 | L2: 10 | M2: TOTALE
A3: Region | B3: India | C3: =COUNTIFS('My trades'!$C:$C, $B3,'My trades'!$E:$E,C$2) -> 4 | D3: =COUNTIFS('My trades'!$C:$C, $B3,'My trades'!$E:$E,D$2) -> 4 | E3: =COUNTIFS('My trades'!$C:$C, $B3,'My trades'!$E:$E,E$2) -> 4 | F3: =COUNTIFS('My trades'!$C:$C, $B3,'My trades'!$E:$E,F$2) -> 1 | G3: =COUNTIFS('My trades'!$C:$C, $B3,'My trades'!$E:$E,G$2) -> 1 | H3: =COUNTIFS('My trades'!$C:$C, $B3,'My trades'!$E:$E,H$2) -> 3 | I3: =COUNTIFS('My trades'!$C:$C, $B3,'My trades'!$E:$E,I$2) -> 2 | J3: =COUNTIFS('My trades'!$C:$C, $B3,'My trades'!$E:$E,J$2) -> 1 | ... L3: =COUNTIFS('My trades'!$C:$C, $B3,'My trades'!$E:$E,L$2) -> 2 | M3: =SUM(C3:L3) -> 24 | O3: Probabilità che una qualunque azione sia stata acquistata in quantità pari a 7 unità nel Regno Unito
B4: Iran | C4: =COUNTIFS('My trades'!$C:$C, $B4,'My trades'!$E:$E,C$2) -> 0 | D4: =COUNTIFS('My trades'!$C:$C, $B4,'My trades'!$E:$E,D$2) -> 2 | E4: =COUNTIFS('My trades'!$C:$C, $B4,'My trades'!$E:$E,E$2) -> 1 | F4: =COUNTIFS('My trades'!$C:$C, $B4,'My trades'!$E:$E,F$2) -> 1 | G4: =COUNTIFS('My trades'!$C:$C, $B4,'My trades'!$E:$E,G$2) -> 1 | H4: =COUNTIFS('My trades'!$C:$C, $B4,'My trades'!$E:$E,H$2) -> 1 | I4: =COUNTIFS('My trades'!$C:$C, $B4,'My trades'!$E:$E,I$2) -> 0 | J4: =COUNTIFS('My trades'!$C:$C, $B4,'My trades'!$E:$E,J$2) -> 1 | ... L4: =COUNTIFS('My trades'!$C:$C, $B4,'My trades'!$E:$E,L$2) -> 1 | M4: =SUM(C4:L4) -> 8 | O4: =I15/M20 -> 0.01
B5: Switzerland | C5: =COUNTIFS('My trades'!$C:$C, $B5,'My trades'!$E:$E,C$2) -> 2 | D5: =COUNTIFS('My trades'!$C:$C, $B5,'My trades'!$E:$E,D$2) -> 0 | E5: =COUNTIFS('My trades'!$C:$C, $B5,'My trades'!$E:$E,E$2) -> 0 | F5: =COUNTIFS('My trades'!$C:$C, $B5,'My trades'!$E:$E,F$2) -> 0 | G5: =COUNTIFS('My trades'!$C:$C, $B5,'My trades'!$E:$E,G$2) -> 0 | H5: =COUNTIFS('My trades'!$C:$C, $B5,'My trades'!$E:$E,H$2) -> 2 | I5: =COUNTIFS('My trades'!$C:$C, $B5,'My trades'!$E:$E,I$2) -> 0 | J5: =COUNTIFS('My trades'!$C:$C, $B5,'My trades'!$E:$E,J$2) -> 2 | ... L5: =COUNTIFS('My trades'!$C:$C, $B5,'My trades'!$E:$E,L$2) -> 1 | M5: =SUM(C5:L5) -> 8
B6: Europe | C6: =COUNTIFS('My trades'!$C:$C, $B6,'My trades'!$E:$E,C$2) -> 3 | D6: =COUNTIFS('My trades'!$C:$C, $B6,'My trades'!$E:$E,D$2) -> 1 | E6: =COUNTIFS('My trades'!$C:$C, $B6,'My trades'!$E:$E,E$2) -> 2 | F6: =COUNTIFS('My trades'!$C:$C, $B6,'My trades'!$E:$E,F$2) -> 3 | G6: =COUNTIFS('My trades'!$C:$C, $B6,'My trades'!$E:$E,G$2) -> 2 | H6: =COUNTIFS('My trades'!$C:$C, $B6,'My trades'!$E:$E,H$2) -> 3 | I6: =COUNTIFS('My trades'!$C:$C, $B6,'My trades'!$E:$E,I$2) -> 0 | J6: =COUNTIFS('My trades'!$C:$C, $B6,'My trades'!$E:$E,J$2) -> 0 | ... L6: =COUNTIFS('My trades'!$C:$C, $B6,'My trades'!$E:$E,L$2) -> 1 | M6: =SUM(C6:L6) -> 16
B7: South Korea | C7: =COUNTIFS('My trades'!$C:$C, $B7,'My trades'!$E:$E,C$2) -> 2 | D7: =COUNTIFS('My trades'!$C:$C, $B7,'My trades'!$E:$E,D$2) -> 0 | E7: =COUNTIFS('My trades'!$C:$C, $B7,'My trades'!$E:$E,E$2) -> 2 | F7: =COUNTIFS('My trades'!$C:$C, $B7,'My trades'!$E:$E,F$2) -> 0 | G7: =COUNTIFS('My trades'!$C:$C, $B7,'My trades'!$E:$E,G$2) -> 0 | H7: =COUNTIFS('My trades'!$C:$C, $B7,'My trades'!$E:$E,H$2) -> 1 | I7: =COUNTIFS('My trades'!$C:$C, $B7,'My trades'!$E:$E,I$2) -> 2 | J7: =COUNTIFS('My trades'!$C:$C, $B7,'My trades'!$E:$E,J$2) -> 1 | ... L7: =COUNTIFS('My trades'!$C:$C, $B7,'My trades'!$E:$E,L$2) -> 0 | M7: =SUM(C7:L7) -> 8
B8: South Africa | C8: =COUNTIFS('My trades'!$C:$C, $B8,'My trades'!$E:$E,C$2) -> 2 | D8: =COUNTIFS('My trades'!$C:$C, $B8,'My trades'!$E:$E,D$2) -> 0 | E8: =COUNTIFS('My trades'!$C:$C, $B8,'My trades'!$E:$E,E$2) -> 1 | F8: =COUNTIFS('My trades'!$C:$C, $B8,'My trades'!$E:$E,F$2) -> 2 | G8: =COUNTIFS('My trades'!$C:$C, $B8,'My trades'!$E:$E,G$2) -> 1 | H8: =COUNTIFS('My trades'!$C:$C, $B8,'My trades'!$E:$E,H$2) -> 1 | I8: =COUNTIFS('My trades'!$C:$C, $B8,'My trades'!$E:$E,I$2) -> 0 | J8: =COUNTIFS('My trades'!$C:$C, $B8,'My trades'!$E:$E,J$2) -> 0 | ... L8: =COUNTIFS('My trades'!$C:$C, $B8,'My trades'!$E:$E,L$2) -> 1 | M8: =SUM(C8:L8) -> 8
B9: Canada | C9: =COUNTIFS('My trades'!$C:$C, $B9,'My trades'!$E:$E,C$2) -> 0 | D9: =COUNTIFS('My trades'!$C:$C, $B9,'My trades'!$E:$E,D$2) -> 2 | E9: =COUNTIFS('My trades'!$C:$C, $B9,'My trades'!$E:$E,E$2) -> 0 | F9: =COUNTIFS('My trades'!$C:$C, $B9,'My trades'!$E:$E,F$2) -> 0 | G9: =COUNTIFS('My trades'!$C:$C, $B9,'My trades'!$E:$E,G$2) -> 2 | H9: =COUNTIFS('My trades'!$C:$C, $B9,'My trades'!$E:$E,H$2) -> 2 | I9: =COUNTIFS('My trades'!$C:$C, $B9,'My trades'!$E:$E,I$2) -> 0 | J9: =COUNTIFS('My trades'!$C:$C, $B9,'My trades'!$E:$E,J$2) -> 0 | ... L9: =COUNTIFS('My trades'!$C:$C, $B9,'My trades'!$E:$E,L$2) -> 2 | M9: =SUM(C9:L9) -> 8
B10: Germany | C10: =COUNTIFS('My trades'!$C:$C, $B10,'My trades'!$E:$E,C$2) -> 1 | D10: =COUNTIFS('My trades'!$C:$C, $B10,'My trades'!$E:$E,D$2) -> 1 | E10: =COUNTIFS('My trades'!$C:$C, $B10,'My trades'!$E:$E,E$2) -> 3 | F10: =COUNTIFS('My trades'!$C:$C, $B10,'My trades'!$E:$E,F$2) -> 0 | G10: =COUNTIFS('My trades'!$C:$C, $B10,'My trades'!$E:$E,G$2) -> 4 | H10: =COUNTIFS('My trades'!$C:$C, $B10,'My trades'!$E:$E,H$2) -> 4 | I10: =COUNTIFS('My trades'!$C:$C, $B10,'My trades'!$E:$E,I$2) -> 1 | J10: =COUNTIFS('My trades'!$C:$C, $B10,'My trades'!$E:$E,J$2) -> 0 | ... L10: =COUNTIFS('My trades'!$C:$C, $B10,'My trades'!$E:$E,L$2) -> 0 | M10: =SUM(C10:L10) -> 16
B11: Saudi Arabia | C11: =COUNTIFS('My trades'!$C:$C, $B11,'My trades'!$E:$E,C$2) -> 1 | D11: =COUNTIFS('My trades'!$C:$C, $B11,'My trades'!$E:$E,D$2) -> 2 | E11: =COUNTIFS('My trades'!$C:$C, $B11,'My trades'!$E:$E,E$2) -> 0 | F11: =COUNTIFS('My trades'!$C:$C, $B11,'My trades'!$E:$E,F$2) -> 0 | G11: =COUNTIFS('My trades'!$C:$C, $B11,'My trades'!$E:$E,G$2) -> 2 | H11: =COUNTIFS('My trades'!$C:$C, $B11,'My trades'!$E:$E,H$2) -> 1 | I11: =COUNTIFS('My trades'!$C:$C, $B11,'My trades'!$E:$E,I$2) -> 2 | J11: =COUNTIFS('My trades'!$C:$C, $B11,'My trades'!$E:$E,J$2) -> 0 | ... L11: =COUNTIFS('My trades'!$C:$C, $B11,'My trades'!$E:$E,L$2) -> 0 | M11: =SUM(C11:L11) -> 8
B12: Japan | C12: =COUNTIFS('My trades'!$C:$C, $B12,'My trades'!$E:$E,C$2) -> 1 | D12: =COUNTIFS('My trades'!$C:$C, $B12,'My trades'!$E:$E,D$2) -> 1 | E12: =COUNTIFS('My trades'!$C:$C, $B12,'My trades'!$E:$E,E$2) -> 1 | F12: =COUNTIFS('My trades'!$C:$C, $B12,'My trades'!$E:$E,F$2) -> 0 | G12: =COUNTIFS('My trades'!$C:$C, $B12,'My trades'!$E:$E,G$2) -> 0 | H12: =COUNTIFS('My trades'!$C:$C, $B12,'My trades'!$E:$E,H$2) -> 2 | I12: =COUNTIFS('My trades'!$C:$C, $B12,'My trades'!$E:$E,I$2) -> 0 | J12: =COUNTIFS('My trades'!$C:$C, $B12,'My trades'!$E:$E,J$2) -> 2 | ... L12: =COUNTIFS('My trades'!$C:$C, $B12,'My trades'!$E:$E,L$2) -> 0 | M12: =SUM(C12:L12) -> 8
B13: Hong Kong | C13: =COUNTIFS('My trades'!$C:$C, $B13,'My trades'!$E:$E,C$2) -> 0 | D13: =COUNTIFS('My trades'!$C:$C, $B13,'My trades'!$E:$E,D$2) -> 0 | E13: =COUNTIFS('My trades'!$C:$C, $B13,'My trades'!$E:$E,E$2) -> 0 | F13: =COUNTIFS('My trades'!$C:$C, $B13,'My trades'!$E:$E,F$2) -> 0 | G13: =COUNTIFS('My trades'!$C:$C, $B13,'My trades'!$E:$E,G$2) -> 3 | H13: =COUNTIFS('My trades'!$C:$C, $B13,'My trades'!$E:$E,H$2) -> 1 | I13: =COUNTIFS('My trades'!$C:$C, $B13,'My trades'!$E:$E,I$2) -> 2 | J13: =COUNTIFS('My trades'!$C:$C, $B13,'My trades'!$E:$E,J$2) -> 0 | ... L13: =COUNTIFS('My trades'!$C:$C, $B13,'My trades'!$E:$E,L$2) -> 1 | M13: =SUM(C13:L13) -> 8 | O13: Probabilità che una qualunque azione sia stata acquistata in quantità non superiore a 8 unità in un qualunque stato asiatico
B14: China | C14: =COUNTIFS('My trades'!$C:$C, $B14,'My trades'!$E:$E,C$2) -> 2 | D14: =COUNTIFS('My trades'!$C:$C, $B14,'My trades'!$E:$E,D$2) -> 1 | E14: =COUNTIFS('My trades'!$C:$C, $B14,'My trades'!$E:$E,E$2) -> 1 | F14: =COUNTIFS('My trades'!$C:$C, $B14,'My trades'!$E:$E,F$2) -> 6 | G14: =COUNTIFS('My trades'!$C:$C, $B14,'My trades'!$E:$E,G$2) -> 1 | H14: =COUNTIFS('My trades'!$C:$C, $B14,'My trades'!$E:$E,H$2) -> 2 | I14: =COUNTIFS('My trades'!$C:$C, $B14,'My trades'!$E:$E,I$2) -> 0 | J14: =COUNTIFS('My trades'!$C:$C, $B14,'My trades'!$E:$E,J$2) -> 1 | ... L14: =COUNTIFS('My trades'!$C:$C, $B14,'My trades'!$E:$E,L$2) -> 0 | M14: =SUM(C14:L14) -> 16 | O14: (India, Iran, South Korea, Saudi Arabia, Japan, Hong Kong, China, Taiwan)
B15: United Kingdom | C15: =COUNTIFS('My trades'!$C:$C, $B15,'My trades'!$E:$E,C$2) -> 1 | D15: =COUNTIFS('My trades'!$C:$C, $B15,'My trades'!$E:$E,D$2) -> 2 | E15: =COUNTIFS('My trades'!$C:$C, $B15,'My trades'!$E:$E,E$2) -> 0 | F15: =COUNTIFS('My trades'!$C:$C, $B15,'My trades'!$E:$E,F$2) -> 1 | G15: =COUNTIFS('My trades'!$C:$C, $B15,'My trades'!$E:$E,G$2) -> 0 | H15: =COUNTIFS('My trades'!$C:$C, $B15,'My trades'!$E:$E,H$2) -> 1 | I15: =COUNTIFS('My trades'!$C:$C, $B15,'My trades'!$E:$E,I$2) -> 2 | J15: =COUNTIFS('My trades'!$C:$C, $B15,'My trades'!$E:$E,J$2) -> 0 | ... L15: =COUNTIFS('My trades'!$C:$C, $B15,'My trades'!$E:$E,L$2) -> 0 | M15: =SUM(C15:L15) -> 8 | O15: =SUM(C3:J3,C7:J7,C12:J12,C13:J13,C14:J14,C18:J18,C4:J4,C11:J11)/M20 -> 0.37
B16: Brazil | C16: =COUNTIFS('My trades'!$C:$C, $B16,'My trades'!$E:$E,C$2) -> 2 | D16: =COUNTIFS('My trades'!$C:$C, $B16,'My trades'!$E:$E,D$2) -> 3 | E16: =COUNTIFS('My trades'!$C:$C, $B16,'My trades'!$E:$E,E$2) -> 1 | F16: =COUNTIFS('My trades'!$C:$C, $B16,'My trades'!$E:$E,F$2) -> 1 | G16: =COUNTIFS('My trades'!$C:$C, $B16,'My trades'!$E:$E,G$2) -> 0 | H16: =COUNTIFS('My trades'!$C:$C, $B16,'My trades'!$E:$E,H$2) -> 1 | I16: =COUNTIFS('My trades'!$C:$C, $B16,'My trades'!$E:$E,I$2) -> 4 | J16: =COUNTIFS('My trades'!$C:$C, $B16,'My trades'!$E:$E,J$2) -> 2 | ... L16: =COUNTIFS('My trades'!$C:$C, $B16,'My trades'!$E:$E,L$2) -> 0 | M16: =SUM(C16:L16) -> 16
B17: United States | C17: =COUNTIFS('My trades'!$C:$C, $B17,'My trades'!$E:$E,C$2) -> 2 | D17: =COUNTIFS('My trades'!$C:$C, $B17,'My trades'!$E:$E,D$2) -> 1 | E17: =COUNTIFS('My trades'!$C:$C, $B17,'My trades'!$E:$E,E$2) -> 3 | F17: =COUNTIFS('My trades'!$C:$C, $B17,'My trades'!$E:$E,F$2) -> 2 | G17: =COUNTIFS('My trades'!$C:$C, $B17,'My trades'!$E:$E,G$2) -> 0 | H17: =COUNTIFS('My trades'!$C:$C, $B17,'My trades'!$E:$E,H$2) -> 1 | I17: =COUNTIFS('My trades'!$C:$C, $B17,'My trades'!$E:$E,I$2) -> 1 | J17: =COUNTIFS('My trades'!$C:$C, $B17,'My trades'!$E:$E,J$2) -> 3 | ... L17: =COUNTIFS('My trades'!$C:$C, $B17,'My trades'!$E:$E,L$2) -> 3 | M17: =SUM(C17:L17) -> 16
B18: Taiwan | C18: =COUNTIFS('My trades'!$C:$C, $B18,'My trades'!$E:$E,C$2) -> 0 | D18: =COUNTIFS('My trades'!$C:$C, $B18,'My trades'!$E:$E,D$2) -> 0 | E18: =COUNTIFS('My trades'!$C:$C, $B18,'My trades'!$E:$E,E$2) -> 1 | F18: =COUNTIFS('My trades'!$C:$C, $B18,'My trades'!$E:$E,F$2) -> 1 | G18: =COUNTIFS('My trades'!$C:$C, $B18,'My trades'!$E:$E,G$2) -> 1 | H18: =COUNTIFS('My trades'!$C:$C, $B18,'My trades'!$E:$E,H$2) -> 0 | I18: =COUNTIFS('My trades'!$C:$C, $B18,'My trades'!$E:$E,I$2) -> 1 | J18: =COUNTIFS('My trades'!$C:$C, $B18,'My trades'!$E:$E,J$2) -> 0 | ... L18: =COUNTIFS('My trades'!$C:$C, $B18,'My trades'!$E:$E,L$2) -> 2 | M18: =SUM(C18:L18) -> 8
B19: Australia | C19: =COUNTIFS('My trades'!$C:$C, $B19,'My trades'!$E:$E,C$2) -> 3 | D19: =COUNTIFS('My trades'!$C:$C, $B19,'My trades'!$E:$E,D$2) -> 2 | E19: =COUNTIFS('My trades'!$C:$C, $B19,'My trades'!$E:$E,E$2) -> 1 | F19: =COUNTIFS('My trades'!$C:$C, $B19,'My trades'!$E:$E,F$2) -> 0 | G19: =COUNTIFS('My trades'!$C:$C, $B19,'My trades'!$E:$E,G$2) -> 3 | H19: =COUNTIFS('My trades'!$C:$C, $B19,'My trades'!$E:$E,H$2) -> 1 | I19: =COUNTIFS('My trades'!$C:$C, $B19,'My trades'!$E:$E,I$2) -> 3 | J19: =COUNTIFS('My trades'!$C:$C, $B19,'My trades'!$E:$E,J$2) -> 1 | ... L19: =COUNTIFS('My trades'!$C:$C, $B19,'My trades'!$E:$E,L$2) -> 2 | M19: =SUM(C19:L19) -> 16
B20: TOTALE | C20: =SUM(C3:C19) -> 26 | D20: =SUM(D3:D19) -> 22 | E20: =SUM(E3:E19) -> 21 | F20: =SUM(F3:F19) -> 18 | G20: =SUM(G3:G19) -> 21 | H20: =SUM(H3:H19) -> 27 | I20: =SUM(I3:I19) -> 20 | J20: =SUM(J3:J19) -> 14 | ... M20: =SUM(M3:M19) -> 200
